Traceback (most recent call last):
  File "/media/jonas/B41ED7D91ED792AA/Arbeit_und_Studium/Kognitionswissenschaft/Semester_5/masterarbeit#/data_Code/code/datasetClasses.py", line 97, in __getitem__
    inpt = functions.openData(self.targets[idx])[np.random.randint(0, 5, size=1)[0], :, :]
IndexError: index 4 is out of bounds for dimension 0 with size 4
During handling of the above exception, another exception occurred:
Traceback (most recent call last):
  File "/media/jonas/B41ED7D91ED792AA/Arbeit_und_Studium/Kognitionswissenschaft/Semester_5/masterarbeit#/data_Code/code/tokenizer.py", line 103, in <module>
    trainTokenizer(model, trainLoader, optimizer, criterion, device, 5, pathOrigin, True)
  File "/media/jonas/B41ED7D91ED792AA/Arbeit_und_Studium/Kognitionswissenschaft/Semester_5/masterarbeit#/data_Code/code/tokenizer.py", line 73, in trainTokenizer
    for inputs in trainLoader:
  File "/home/jonas/.local/lib/python3.10/site-packages/torch/utils/data/dataloader.py", line 628, in __next__
    data = self._next_data()
  File "/home/jonas/.local/lib/python3.10/site-packages/torch/utils/data/dataloader.py", line 671, in _next_data
    data = self._dataset_fetcher.fetch(index)  # may raise StopIteration
  File "/home/jonas/.local/lib/python3.10/site-packages/torch/utils/data/_utils/fetch.py", line 58, in fetch
    data = [self.dataset[idx] for idx in possibly_batched_index]
  File "/home/jonas/.local/lib/python3.10/site-packages/torch/utils/data/_utils/fetch.py", line 58, in <listcomp>
    data = [self.dataset[idx] for idx in possibly_batched_index]
  File "/media/jonas/B41ED7D91ED792AA/Arbeit_und_Studium/Kognitionswissenschaft/Semester_5/masterarbeit#/data_Code/code/datasetClasses.py", line 101, in __getitem__
    inpt = functions.openData(self.images[index])[np.random.randint(0, 5, size=1)[0], :, :]
IndexError: index 4 is out of bounds for dimension 0 with size 4
Traceback (most recent call last):
  File "/media/jonas/B41ED7D91ED792AA/Arbeit_und_Studium/Kognitionswissenschaft/Semester_5/masterarbeit#/data_Code/code/datasetClasses.py", line 97, in __getitem__
    inpt = functions.openData(self.targets[idx])[np.random.randint(0, 5, size=1)[0], :, :]
IndexError: index 4 is out of bounds for dimension 0 with size 4
During handling of the above exception, another exception occurred:
Traceback (most recent call last):
  File "/media/jonas/B41ED7D91ED792AA/Arbeit_und_Studium/Kognitionswissenschaft/Semester_5/masterarbeit#/data_Code/code/tokenizer.py", line 103, in <module>
    trainTokenizer(model, trainLoader, optimizer, criterion, device, 5, pathOrigin, True)
  File "/media/jonas/B41ED7D91ED792AA/Arbeit_und_Studium/Kognitionswissenschaft/Semester_5/masterarbeit#/data_Code/code/tokenizer.py", line 73, in trainTokenizer
    for inputs in trainLoader:
  File "/home/jonas/.local/lib/python3.10/site-packages/torch/utils/data/dataloader.py", line 628, in __next__
    data = self._next_data()
  File "/home/jonas/.local/lib/python3.10/site-packages/torch/utils/data/dataloader.py", line 671, in _next_data
    data = self._dataset_fetcher.fetch(index)  # may raise StopIteration
  File "/home/jonas/.local/lib/python3.10/site-packages/torch/utils/data/_utils/fetch.py", line 58, in fetch
    data = [self.dataset[idx] for idx in possibly_batched_index]
  File "/home/jonas/.local/lib/python3.10/site-packages/torch/utils/data/_utils/fetch.py", line 58, in <listcomp>
    data = [self.dataset[idx] for idx in possibly_batched_index]
  File "/media/jonas/B41ED7D91ED792AA/Arbeit_und_Studium/Kognitionswissenschaft/Semester_5/masterarbeit#/data_Code/code/datasetClasses.py", line 101, in __getitem__
    inpt = functions.openData(self.images[index])[np.random.randint(0, 5, size=1)[0], :, :]
IndexError: index 4 is out of bounds for dimension 0 with size 4